Workbook

Sheet Bill Rates
A1: Onyx Accounting Group, LLC
A2: Average Bill Rates by Client — 2026
A3: 2026 standard rates per client, with July-2026 Harvest actuals alongside. The blend method on the Assumptions tab decides which average drives the model.
A5: Client Group | B5: Client / Entity | C5: CFO | D5: Controller | E5: Staff | F5: Jul-26 billable hrs | G5: Jul-26 billable $ | H5: Jul-26 effective $/hr
A6: Mohrschladt Entities | B6: 1402 Victory Lane LLC | C6: 250 | D6: 145 | E6: 95 | F6: 1.2 | G6: 222.5 | H6: =IF(N(F6)=0,"",G6/F6) -> 185.41667
B7: 3540 E Boot Track, LLC | C7: 250 | D7: 145 | E7: 95 | F7: 3 | G7: 393.5 | H7: =IF(N(F7)=0,"",G7/F7) -> 131.16667
B8: 4530 W. Flint, LLC | C8: 250 | D8: 145 | E8: 95 | F8: 2 | G8: 298.5 | H8: =IF(N(F8)=0,"",G8/F8) -> 149.25
B9: 7327 Tierra Buena LLC | C9: 250 | D9: 145 | E9: 95 | F9: 2.7 | G9: 365 | H9: =IF(N(F9)=0,"",G9/F9) -> 135.18519
B10: 15650 Northsight LLC | C10: 250 | D10: 145 | E10: 95 | F10: 2.3 | G10: 420 | H10: =IF(N(F10)=0,"",G10/F10) -> 182.6087
B11: Barrett Living Trust | C11: 250 | D11: 145 | E11: 95 | F11: 6.5 | G11: 617.5 | H11: =IF(N(F11)=0,"",G11/F11) -> 95
B12: Catalpa Industrial Park, Inc. | C12: 250 | D12: 145 | E12: 95 | F12: 7.7 | G12: 840 | H12: =IF(N(F12)=0,"",G12/F12) -> 109.09091
B13: Mohrschladt Capital, LP | C13: 250 | D13: 145 | E13: 95 | H13: =IF(N(F13)=0,"",G13/F13) | I13: no July time — dormant
B14: Mohrschladt Howarth Associates, Inc. | C14: 250 | D14: 145 | E14: 95 | F14: 2.7 | G14: 473.5 | H14: =IF(N(F14)=0,"",G14/F14) -> 175.37037
B15: NEWPORT CLASSIC CARS LLC | C15: 250 | D15: 145 | E15: 95 | F15: 1.2 | G15: 191.5 | H15: =IF(N(F15)=0,"",G15/F15) -> 159.58333
B16: Obsidian Real Estate | C16: 250 | D16: 145 | E16: 95 | F16: 10.2 | G16: 1201.5 | H16: =IF(N(F16)=0,"",G16/F16) -> 117.79412
B17: Paradise Village LLC | C17: 250 | D17: 145 | E17: 95 | F17: 1 | G17: 95 | H17: =IF(N(F17)=0,"",G17/F17) -> 95
B18: Rancho Industrial Park, Inc. | C18: 250 | D18: 145 | E18: 95 | F18: 9 | G18: 1010 | H18: =IF(N(F18)=0,"",G18/F18) -> 112.22222
A19: Tavasci Entities | B19: 7730 Evans, LLC | C19: 250 | D19: 145 | E19: 95 | F19: 2.1 | G19: 246 | H19: =IF(N(F19)=0,"",G19/F19) -> 117.14286
B20: 909 Main, LLC | C20: 250 | D20: 145 | E20: 95 | F20: 3 | G20: 393.5 | H20: =IF(N(F20)=0,"",G20/F20) -> 131.16667
B21: Capital Financial, LLC | C21: 250 | D21: 145 | E21: 95 | F21: 18.5 | G21: 2021 | H21: =IF(N(F21)=0,"",G21/F21) -> 109.24324
B22: DQCC | C22: 250 | D22: 145 | E22: 95 | F22: 1.1 | G22: 151 | H22: =IF(N(F22)=0,"",G22/F22) -> 137.27273
B23: Educational Services, LLC | C23: 250 | D23: 145 | E23: 95 | F23: 1.3 | G23: 325 | H23: =IF(N(F23)=0,"",G23/F23) -> 250
B24: Educational Services Holdings LLC | C24: 250 | D24: 145 | E24: 95 | F24: 7.9 | G24: 1386 | H24: =IF(N(F24)=0,"",G24/F24) -> 175.44304
B25: KAMM ADGT | C25: 250 | D25: 145 | E25: 95 | F25: 1.1 | G25: 151 | H25: =IF(N(F25)=0,"",G25/F25) -> 137.27273
B26: Tavasci Personal | C26: 250 | D26: 145 | E26: 95 | H26: =IF(N(F26)=0,"",G26/F26) | I26: no July time — dormant
B27: Edcuational Services Intermediate, LLC | C27: 250 | D27: 145 | E27: 95 | H27: =IF(N(F27)=0,"",G27/F27) | I27: no July time — dormant
B28: International Alliance Group LLC | C28: 250 | D28: 145 | E28: 95 | F28: 218.4 | G28: 31142.5 | H28: =IF(N(F28)=0,"",G28/F28) -> 142.59386
B29: Little Moo's | C29: 250 | D29: 145 | E29: 95 | F29: 3.3 | G29: 360 | H29: =IF(N(F29)=0,"",G29/F29) -> 109.09091
B30: T5 Family Holdings, LLC | C30: 250 | D30: 145 | E30: 95 | F30: 12 | G30: 1341.5 | H30: =IF(N(F30)=0,"",G30/F30) -> 111.79167
B31: Tavasci Brothers Motorsports | C31: 250 | D31: 145 | E31: 95 | F31: 2.6 | G31: 293.5 | H31: =IF(N(F31)=0,"",G31/F31) -> 112.88462
B32: TSCC54, LLC | C32: 250 | D32: 145 | E32: 95 | H32: =IF(N(F32)=0,"",G32/F32) | I32: no July time — dormant
B33: VVI 1017 | C33: 250 | D33: 145 | E33: 95 | F33: 3.1 | G33: 418.5 | H33: =IF(N(F33)=0,"",G33/F33) -> 135
B34: VVNS | C34: 250 | D34: 145 | E34: 95 | F34: 26.8 | G34: 6033.5 | H34: =IF(N(F34)=0,"",G34/F34) -> 225.1306
A35: BeckShar | B35: BeckShar Development | C35: 250 | D35: 175 | E35: 100 | F35: 11.8 | G35: 2275 | H35: =IF(N(F35)=0,"",G35/F35) -> 192.79661
B36: BeckShar LLC | F36: 5.7 | G36: 570 | H36: =IF(N(F36)=0,"",G36/F36) -> 100
B37: BeckShar Diamond Commercial | F37: 0.7 | G37: 70 | H37: =IF(N(F37)=0,"",G37/F37) -> 100
B38: BSD Contracting LLC | F38: 1 | G38: 100 | H38: =IF(N(F38)=0,"",G38/F38) -> 100
A39: Midwest | B39: Midwest Contracting, Inc | C39: 250 | D39: 185 | E39: 100 | F39: 66.1 | G39: 10360 | H39: =IF(N(F39)=0,"",G39/F39) -> 156.73222
B40: Eight Eleven | F40: 46.2 | G40: 6045 | H40: =IF(N(F40)=0,"",G40/F40) -> 130.84416
B41: Southwest Rentals | F41: 10 | G41: 1900 | H41: =IF(N(F41)=0,"",G41/F41) -> 190
...

Sheet Assumptions
A1: Onyx Accounting Group, LLC
A2: Assumptions & Drivers
A3: Change any yellow cell to re-forecast the whole model.
A5: TIME & UTILIZATION
A6: Hours per week | B6: 40 | C6: Firm standard schedule
A7: Weeks per month | B7: 4 | C7: Legacy flat convention — superseded by the Monthly Capacity calendar
A8: Gross working hours per month | B8: =B6*B7 -> 160 | C8: 40 × 4 = 160 (flat). Real calendar averages 169.3 hrs/mo
A9: Non-billable admin hours per month | B9: 20 | C9: Per your spec
A10: Billable-eligible hours per month | B10: =B8-B9 -> 140 | C10: Flat basis only — superseded by Monthly Capacity
A11: PTO hours per year | B11: 80 | C11: 2 weeks — Onyx Handbook
A12: Paid holiday hours per year | B12: 56 | C12: 7 holidays × 8 hrs — Onyx Handbook
A13: PTO + holiday per month | B13: =(B11+B12)/12 -> 11.333333 | C13: Flat basis only — Monthly Capacity handles PTO and holidays by month
A14: Available billable hrs / mo (100% util) | B14: =B10-B13 -> 128.66667 | C14: Flat basis only — superseded by Monthly Capacity
A15: Utilization % — firm default | B15: 0.91 | C15: Starting point for every person. Override per person in Monthly Capacity column T.
A16: Paid hours per year (full-time) | B16: ='Monthly Capacity'!$N$14 -> 2088 | C16: Weekdays × 8 from the 2026 calendar (2,088) — divisor for hourly pay & loaded cost
A17: ↑ flat-basis block above is legacy; Monthly Capacity is the live driver
A18: EMPLOYER PAYROLL TAXES (AZ / US)
A19: Social Security — employer rate | B19: 0.062 | C19: FICA OASDI, capped at wage base
A20: Social Security wage base (2026) | B20: 184500 | C20: 2026 SSA max
A21: Medicare — employer rate | B21: 0.0145 | C21: Uncapped
A22: FUTA rate | B22: 0.006 | C22: Federal unemployment (net)
A23: FUTA wage base | B23: 7000 | C23: First $7,000 of wages
A24: AZ SUTA rate | B24: 0.0139 | C24: Arizona unemployment — set to your rate
A25: AZ SUTA wage base | B25: 8000 | C25: First $8,000 of wages (AZ 2026)
A27: OWNER COMPENSATION
A28: Owner (Steven) annual salary | B28: 184500 | C28: Set to Social Security wage-base max
A29: Owner client (billable) share | B29: 0.5 | C29: 50% client / 50% admin per your split
A30: Owner admin (overhead) share | B30: =1-B29 -> 0.5 | C30: flows to Operating Expenses
A32: BLENDED BILL RATES — 2026 (from Bill Rates tab)
A33: CFO average bill rate | B33: =CHOOSE($B$36,'Bill Rates'!$C$62,'Bill Rates'!$C$65,'Bill Rates'!$C$72) -> 246.57126 | C33: Steven, Lisa — follows the method in B36
A34: Controller average bill rate | B34: =CHOOSE($B$36,'Bill Rates'!$D$62,'Bill Rates'!$D$65,'Bill Rates'!$D$72) -> 151.11296 | C34: Jessica — follows the method in B36
A35: Staff average bill rate | B35: =CHOOSE($B$36,'Bill Rates'!$E$62,'Bill Rates'!$E$65,'Bill Rates'!$E$72) -> 94.988641 | C35: Christine, Valentina, Josephine — follows the method in B36
A36: Rate blend method (1, 2 or 3) | B36: 3 | C36: 1 = simple average · 2 = hours-weighted · 3 = calibrated to July actuals
A38: OWNER HOURS MODE (1 or 2) | B38: 1 | C38: 1 = fixed 50% share (today) · 2 = residual to hit a net-income target
A40: BONUS FACTOR SOURCE (1 or 2) | B40: 1 | C40: 1 = the manual quarterly factors · 2 = the earned scorecard factor

Sheet Staff P&L
A1: Onyx Accounting Group, LLC
A2: Staff P&L — Pay, Labor Burden & Gross Profit per Person
A3: Blue = input. Loaded hourly cost = full burden (pay + AZ/US tax + PEO benefits) ÷ paid hours (2,088 from the 2026 calendar). Hours & revenue now come from the Monthly Capacity tab.
D4: COMPENSATION & EMPLOYER BURDEN | P4: HOURS, REVENUE & GROSS PROFIT
A5: Employee | B5: Role | C5: Pay basis | D5: Pay rate / salary | E5: Base annual comp | F5: Empl. SS | G5: Empl. Medicare | H5: FUTA | I5: AZ SUTA | J5: Total empl. tax | K5: Benefits $/mo (2026 avg) | L5: Benefits annual | M5: Fully-loaded annual cost (incl. bonus) | N5: Loaded cost /mo | O5: Loaded cost /hr | P5: Billable hrs /yr | Q5: Billable hrs /mo (avg) | R5: Bill rate | S5: Revenue /mo | T5: COGS alloc % | U5: COGS cost /mo | V5: OpEx cost /mo | W5: Gross profit /mo | X5: GP margin
A6: Steven Nikolov | B6: CFO | C6: Salary (owner) | D6: =Assumptions!$B$28 -> 184500 | E6: =D6 -> 184500 | F6: =Assumptions!$B$19*MIN(E6,Assumptions!$B$20) -> 11439 | G6: =Assumptions!$B$21*E6 -> 2675.25 | H6: =Assumptions!$B$22*MIN(E6,Assumptions!$B$23) -> 42 | I6: =Assumptions!$B$24*MIN(E6,Assumptions!$B$25) -> 111.2 | J6: =SUM(F6:I6) -> 14267.45 | K6: =Benefits!$G$19 -> 345.24833 | L6: =K6*12 -> 4142.98 | M6: =E6+J6+L6+J18 -> 202910.43 | N6: =M6/12 -> 16909.202 | O6: =M6/Assumptions!$B$16 -> 97.179325 | P6: ='Monthly Capacity'!$N$22 -> 888.16 | Q6: =P6/12 -> 74.013333 | R6: =Assumptions!$B$33 -> 246.57126 | S6: ='Monthly Capacity'!$N$31/12 -> 18249.561 | T6: =IF(Assumptions!$B$38=2,IFERROR(MIN(1,'Monthly Capacity'!$N$22/('Monthly Capacity'!$N$13-'Monthly Capacity'!$P$22*12-'Monthly Capacity'!$R$22)),0),Assumptions!$B$29) -> 0.5 | U6: =N6*T6 -> 8454.6012 | V6: =N6*(1-T6) -> 8454.6012 | W6: =S6-U6 -> 9794.9594 | X6: =IF(S6=0,0,W6/S6) -> 0.53672302
A7: Lisa Danforth | B7: CFO | C7: Salary | D7: 176000 | E7: =D7 -> 176000 | F7: =Assumptions!$B$19*MIN(E7,Assumptions!$B$20) -> 10912 | G7: =Assumptions!$B$21*E7 -> 2552 | H7: =Assumptions!$B$22*MIN(E7,Assumptions!$B$23) -> 42 | I7: =Assumptions!$B$24*MIN(E7,Assumptions!$B$25) -> 111.2 | J7: =SUM(F7:I7) -> 13617.2 | K7: =Benefits!$G$20 -> 341.70667 | L7: =K7*12 -> 4100.48 | M7: =E7+J7+L7+J19 -> 193717.68 | N7: =M7/12 -> 16143.14 | O7: =M7/Assumptions!$B$16 -> 92.776667 | P7: ='Monthly Capacity'!$N$23 -> 1557.92 | Q7: =P7/12 -> 129.82667 | R7: =Assumptions!$B$33 -> 246.57126 | S7: ='Monthly Capacity'!$N$32/12 -> 32011.524 | T7: 1 | U7: =N7*T7 -> 16143.14 | V7: =N7*(1-T7) -> 0 | W7: =S7-U7 -> 15868.384 | X7: =IF(S7=0,0,W7/S7) -> 0.49570849
A8: Jessica Bumphus | B8: Controller | C8: Hourly | D8: 60 | E8: =D8*Assumptions!$B$16 -> 125280 | F8: =Assumptions!$B$19*MIN(E8,Assumptions!$B$20) -> 7767.36 | G8: =Assumptions!$B$21*E8 -> 1816.56 | H8: =Assumptions!$B$22*MIN(E8,Assumptions!$B$23) -> 42 | I8: =Assumptions!$B$24*MIN(E8,Assumptions!$B$25) -> 111.2 | J8: =SUM(F8:I8) -> 9737.12 | K8: =Benefits!$G$21 -> 236.05167 | L8: =K8*12 -> 2832.62 | M8: =E8+J8+L8+J20 -> 137849.74 | N8: =M8/12 -> 11487.478 | O8: =M8/Assumptions!$B$16 -> 66.01999 | P8: ='Monthly Capacity'!$N$24 -> 1557.92 | Q8: =P8/12 -> 129.82667 | R8: =Assumptions!$B$34 -> 151.11296 | S8: ='Monthly Capacity'!$N$33/12 -> 19618.491 | T8: 1 | U8: =N8*T8 -> 11487.478 | V8: =N8*(1-T8) -> 0 | W8: =S8-U8 -> 8131.013 | X8: =IF(S8=0,0,W8/S8) -> 0.41445659
A9: Christine Johnson | B9: Staff | C9: Hourly | D9: 40 | E9: =D9*Assumptions!$B$16 -> 83520 | F9: =Assumptions!$B$19*MIN(E9,Assumptions!$B$20) -> 5178.24 | G9: =Assumptions!$B$21*E9 -> 1211.04 | H9: =Assumptions!$B$22*MIN(E9,Assumptions!$B$23) -> 42 | I9: =Assumptions!$B$24*MIN(E9,Assumptions!$B$25) -> 111.2 | J9: =SUM(F9:I9) -> 6542.48 | K9: =Benefits!$G$22 -> 119.78833 | L9: =K9*12 -> 1437.46 | M9: =E9+J9+L9+J21 -> 94197.218 | N9: =M9/12 -> 7849.7682 | O9: =M9/Assumptions!$B$16 -> 45.11361 | P9: ='Monthly Capacity'!$N$25 -> 1557.92 | Q9: =P9/12 -> 129.82667 | R9: =Assumptions!$B$35 -> 94.988641 | S9: ='Monthly Capacity'!$N$34/12 -> 12332.059 | T9: 1 | U9: =N9*T9 -> 7849.7682 | V9: =N9*(1-T9) -> 0 | W9: =S9-U9 -> 4482.2905 | X9: =IF(S9=0,0,W9/S9) -> 0.36346652
A10: Valentina Dikova | B10: Staff | C10: Contractor (BG) | D10: 4200 | E10: =D10*12 -> 50400 | F10: 0 | G10: 0 | H10: 0 | I10: 0 | J10: =SUM(F10:I10) -> 0 | K10: =Benefits!$G$23 -> 0 | L10: =K10*12 -> 0 | M10: =E10+J10+L10+J22 -> 50400 | N10: =M10/12 -> 4200 | O10: =M10/Assumptions!$B$16 -> 24.137931 | P10: ='Monthly Capacity'!$N$26 -> 1630.72 | Q10: =P10/12 -> 135.89333 | R10: =Assumptions!$B$35 -> 94.988641 | S10: ='Monthly Capacity'!$N$35/12 -> 12908.323 | T10: 1 | U10: =N10*T10 -> 4200 | V10: =N10*(1-T10) -> 0 | W10: =S10-U10 -> 8708.3231 | X10: =IF(S10=0,0,W10/S10) -> 0.67462853
A11: Josephine Mack | B11: Admin/Staff | C11: Salary | D11: 80000 | E11: =D11 -> 80000 | F11: =Assumptions!$B$19*MIN(E11,Assumptions!$B$20) -> 4960 | G11: =Assumptions!$B$21*E11 -> 1160 | H11: =Assumptions!$B$22*MIN(E11,Assumptions!$B$23) -> 42 | I11: =Assumptions!$B$24*MIN(E11,Assumptions!$B$25) -> 111.2 | J11: =SUM(F11:I11) -> 6273.2 | K11: =Benefits!$G$24 -> 118.32167 | L11: =K11*12 -> 1419.86 | M11: =E11+J11+L11+J23 -> 104055.86 | N11: =M11/12 -> 8671.3217 | O11: =M11/Assumptions!$B$16 -> 49.835182 | P11: ='Monthly Capacity'!$N$27 -> 266.448 | Q11: =P11/12 -> 22.204 | R11: =Assumptions!$B$35 -> 94.988641 | S11: ='Monthly Capacity'!$N$36/12 -> 2109.1278 | T11: 0.15 | U11: =N11*T11 -> 1300.6982 | V11: =N11*(1-T11) -> 7370.6234 | W11: =S11-U11 -> 808.42954 | X11: =IF(S11=0,0,W11/S11) -> 0.38330041
A12: TOTAL / FIRM | E12: =SUM(E6:E11) -> 699700 | F12: =SUM(F6:F11) -> 40256.6 | G12: =SUM(G6:G11) -> 9414.85 | H12: =SUM(H6:H11) -> 210 | I12: =SUM(I6:I11) -> 556 | J12: =SUM(J6:J11) -> 50437.45 | K12: =SUM(K6:K11) -> 1161.1167 | L12: =SUM(L6:L11) -> 13933.4 | ... N12: =SUM(N6:N11) -> 65260.911 | O12: =M12/Assumptions!$B$16 -> 375.06271 | P12: =SUM(P6:P11) -> 7459.088 | Q12: =SUM(Q6:Q11) -> 621.59067 | S12: =SUM(S6:S11) -> 97229.086 | U12: =SUM(U6:U11) -> 49435.686 | V12: =SUM(V6:V11) -> 15825.225 | W12: =SUM(W6:W11) -> 47793.4 | X12: =IF(S12=0,0,W12/S12) -> 0.49155455
A15: QUARTERLY DISCRETIONARY BONUS | K15: Owner is excluded by policy — set his target to 0%.
A16: Discretionary payout factor | D16: 0 | E16: 0 | F16: 2 | G16: 2 | K16: ← the discretionary lever: 0% pays nothing that quarter, 150% pays one-and-a-half target.
A17: Employee | B17: Target % of base | C17: Annual target | D17: Q1 (Mar) | E17: Q2 (Jun) | F17: Q3 (Sep) | G17: Q4 (Dec) | H17: Annual bonus | I17: Empl. tax on bonus | J17: Total bonus cost
A18: =A6 -> Steven Nikolov | B18: 0 | C18: =E6*B18 -> 0 | D18: =$C18/4*D$16 -> 0 | E18: =$C18/4*E$16 -> 0 | F18: =$C18/4*F$16 -> 0 | G18: =$C18/4*G$16 -> 0 | H18: =SUM(D18:G18) -> 0 | I18: =Assumptions!$B$19*MIN(H18,MAX(0,Assumptions!$B$20-E6))+Assumptions!$B$21*H18 -> 0 | J18: =H18+I18 -> 0
A19: =A7 -> Lisa Danforth | B19: 0 | C19: =E7*B19 -> 0 | D19: =$C19/4*IF(Assumptions!$B$40=2,IF(D$16>0,$H$42,0),D$16) -> 0 | E19: =$C19/4*IF(Assumptions!$B$40=2,IF(E$16>0,$H$42,0),E$16) -> 0 | F19: =$C19/4*IF(Assumptions!$B$40=2,IF(F$16>0,$H$42,0),F$16) -> 0 | G19: =$C19/4*IF(Assumptions!$B$40=2,IF(G$16>0,$H$42,0),G$16) -> 0 | H19: =SUM(D19:G19) -> 0 | I19: =Assumptions!$B$19*MIN(H19,MAX(0,Assumptions!$B$20-E7))+Assumptions!$B$21*H19 -> 0 | J19: =H19+I19 -> 0
A20: =A8 -> Jessica Bumphus | B20: 0 | C20: =E8*B20 -> 0 | D20: =$C20/4*IF(Assumptions!$B$40=2,IF(D$16>0,$I$42,0),D$16) -> 0 | E20: =$C20/4*IF(Assumptions!$B$40=2,IF(E$16>0,$I$42,0),E$16) -> 0 | F20: =$C20/4*IF(Assumptions!$B$40=2,IF(F$16>0,$I$42,0),F$16) -> 0 | G20: =$C20/4*IF(Assumptions!$B$40=2,IF(G$16>0,$I$42,0),G$16) -> 0 | H20: =SUM(D20:G20) -> 0 | I20: =Assumptions!$B$19*MIN(H20,MAX(0,Assumptions!$B$20-E8))+Assumptions!$B$21*H20 -> 0 | J20: =H20+I20 -> 0
A21: =A9 -> Christine Johnson | B21: 0.03 | C21: =E9*B21 -> 2505.6 | D21: =$C21/4*IF(Assumptions!$B$40=2,IF(D$16>0,$J$42,0),D$16) -> 0 | E21: =$C21/4*IF(Assumptions!$B$40=2,IF(E$16>0,$J$42,0),E$16) -> 0 | F21: =$C21/4*IF(Assumptions!$B$40=2,IF(F$16>0,$J$42,0),F$16) -> 1252.8 | G21: =$C21/4*IF(Assumptions!$B$40=2,IF(G$16>0,$J$42,0),G$16) -> 1252.8 | H21: =SUM(D21:G21) -> 2505.6 | I21: =Assumptions!$B$19*MIN(H21,MAX(0,Assumptions!$B$20-E9))+Assumptions!$B$21*H21 -> 191.6784 | J21: =H21+I21 -> 2697.2784
A22: =A10 -> Valentina Dikova | B22: 0 | C22: =E10*B22 -> 0 | D22: =$C22/4*D$16 -> 0 | E22: =$C22/4*E$16 -> 0 | F22: =$C22/4*F$16 -> 0 | G22: =$C22/4*G$16 -> 0 | H22: =SUM(D22:G22) -> 0 | I22: 0 | J22: =H22+I22 -> 0
A23: =A11 -> Josephine Mack | B23: 0.19 | C23: =E11*B23 -> 15200 | D23: =$C23/4*D$16 -> 0 | E23: =$C23/4*E$16 -> 0 | F23: =$C23/4*F$16 -> 7600 | G23: =$C23/4*G$16 -> 7600 | H23: =SUM(D23:G23) -> 15200 | I23: =Assumptions!$B$19*MIN(H23,MAX(0,Assumptions!$B$20-E11))+Assumptions!$B$21*H23 -> 1162.8 | J23: =H23+I23 -> 16362.8
A24: TOTAL BONUS (all) | C24: =SUM(C18:C23) -> 17705.6 | D24: =SUM(D18:D23) -> 0 | E24: =SUM(E18:E23) -> 0 | F24: =SUM(F18:F23) -> 8852.8 | G24: =SUM(G18:G23) -> 8852.8 | H24: =SUM(H18:H23) -> 17705.6 | I24: =SUM(I18:I23) -> 1354.4784 | J24: =SUM(J18:J23) -> 19060.078
A25: of which W-2 payroll → Budget P&L | C25: =C18+C19+C20+C21+C23 -> 17705.6 | D25: =D18+D19+D20+D21+D23 -> 0 | E25: =E18+E19+E20+E21+E23 -> 0 | F25: =F18+F19+F20+F21+F23 -> 8852.8 | G25: =G18+G19+G20+G21+G23 -> 8852.8 | H25: =H18+H19+H20+H21+H23 -> 17705.6 | I25: =I18+I19+I20+I21+I23 -> 1354.4784 | J25: =J18+J19+J20+J21+J23 -> 19060.078
A26: of which contractor → Cost of labor | C26: =C22 -> 0 | D26: =D22 -> 0 | E26: =E22 -> 0 | F26: =F22 -> 0 | G26: =G22 -> 0 | H26: =H22 -> 0 | I26: =I22 -> 0 | J26: =J22 -> 0
A28: • Bonuses are paid in March, June, September and December. Quarterly amount = annual target ÷ 4 × that quarter's payout factor.
A29: • Fully-loaded annual cost in column M includes the bonus and its employer tax, so loaded cost per hour and gross profit per person already reflect the plan.
A30: • The Budget P&L 'Discretionary Bonuses' line and the employer tax on it are driven by the W-2 subtotal. On Forecast 2026 only the September and December payments land in the budget months — March and June are inside the Jan–Jul actuals.
A31: • Valentina is a contractor, so her bonus is not payroll. It sits inside her fully-loaded cost and reaches the P&L through 'Cost of labor - Contractors', spread evenly across the months rather than in four payments. The annual amount is the same either way.
A32: • For reference, actual bonuses paid Jan–Jul 2026 were $2,610 for the whole firm — the 5% target here is a placeholder, so set each person's target before relying on the numbers.
A34: OPERATIONAL BONUS SCORECARD — earns the payout factor instead of typing it
A35: Set the KPI actuals each quarter; the factor is earned. Switch Assumptions!B40 to 2 to let this drive the bonus instead of the manual factors above.
A36: KPI | B36: Direction | C36: Threshold (50%) | D36: Target (100%) | E36: Stretch (150%) | F36: Actual | G36: Earned multiplier | H36: Weight Lisa | I36: Weight Jessica | J36: Weight Christine
A37: Personal billable hours vs the Monthly Capacity plan | B37: higher | C37: 0.85 | D37: 1 | E37: 1.1 | F37: 0.97 | G37: =IF((F37-C37)/(D37-C37)<0,0,IF((F37-D37)/(E37-D37)<0,0.5+0.5*(F37-C37)/(D37-C37),MIN(1.5,1+0.5*(F37-D37)/(E37-D37)))) -> 0.9 | H37: 0.3 | I37: 0.4 | J37: 0.55 | K37: Harvest hours ÷ that person's plan hours. July firm-wide came in at 97% of plan.
A38: Realized revenue per billable hour (3-month average) | B38: higher | C38: 145 | D38: 158 | E38: 170 | F38: 156.42 | G38: =IF((F38-C38)/(D38-C38)<0,0,IF((F38-D38)/(E38-D38)<0,0.5+0.5*(F38-C38)/(D38-C38),MIN(1.5,1+0.5*(F38-D38)/(E38-D38)))) -> 0.93923077 | H38: 0.3 | I38: 0.25 | J38: 0.15 | K38: Collections ÷ billable hours, lagged so it is not gamed by a single month.
A39: Days from work performed to invoice sent | B39: lower | C39: 45 | D39: 30 | E39: 20 | F39: 35 | G39: =IF((F39-C39)/(D39-C39)<0,0,IF((F39-D39)/(E39-D39)<0,0.5+0.5*(F39-C39)/(D39-C39),MIN(1.5,1+0.5*(F39-D39)/(E39-D39)))) -> 0.83333333 | H39: 0.15 | I39: 0.2 | J39: 0.2 | K39: The one metric that fixes the invoice lag. Needs a Harvest/QBO date report.
A40: Net revenue retention on the clients they own | B40: higher | C40: 0.95 | D40: 1.05 | E40: 1.15 | F40: 1 | G40: =IF((F40-C40)/(D40-C40)<0,0,IF((F40-D40)/(E40-D40)<0,0.5+0.5*(F40-C40)/(D40-C40),MIN(1.5,1+0.5*(F40-D40)/(E40-D40)))) -> 0.75 | H40: 0.25 | I40: 0.15 | J40: 0.1 | K40: This year's fees ÷ last year's, same client group. Set the groups first.
A41: Total weight — each column must add to 100% | H41: =SUM(H37:H40) -> 1 | I41: =SUM(I37:I40) -> 1 | J41: =SUM(J37:J40) -> 1 | K41: =IF(AND(ROUND(H41,4)=1,ROUND(I41,4)=1,ROUND(J41,4)=1),"weights OK","FIX — each weight column must total 100%") -> weights OK
A42: EARNED PAYOUT FACTOR | H42: =SUMPRODUCT($G$37:$G$40,H37:H40) -> 0.86426923 | I42: =SUMPRODUCT($G$37:$G$40,I37:I40) -> 0.87397436 | J42: =SUMPRODUCT($G$37:$G$40,J37:J40) -> 0.87755128
A44: RECOMMENDED TARGET BONUS % OF BASE
A45: Lisa Danforth (CFO) | C45: 0.12 | K45: owns client relationships and pricing — most leverage
...

Sheet Benefits
A1: Onyx Accounting Group, LLC
A2: Benefits — Health Insurance, 401(k) and PEO Fees
A3: Insperity HR360 proposal, Liberty Saver, 1000 Deductible plan. Prepared 12 Aug 2026, bid expires 25 Sep 2026, anticipated start 25 Oct 2026.
A4: Insperity's own default has the client paying a FLAT $509.76 per employee at every tier. Your $338 / $676 / $1,014 policy is a decision to subsidise DEPENDENT coverage.
A6: 1. EMPLOYEE CONTRIBUTION POLICY
A7: Base employee price — employee only | B7: 338 | H7: Your target. Insperity's own default for this tier is $338.17, so this matches it.
A9: 2. 1000 DEDUCTIBLE PLAN — TIERS
A10: Coverage tier | B10: Total monthly allocation | C10: Employee multiple | D10: Employee pays | E10: Employer pays | F10: Insperity default employer
A11: Employee Only | B11: 847.93 | C11: 1 | D11: =$B$7*C11 -> 338 | E11: =MAX(0,B11-D11) -> 509.93 | F11: 509.76 | H11: Insperity default employee price is $338.17 — your policy matches
A12: Emp. + Spouse | B12: 1779.11 | C12: 2 | D12: =$B$7*C12 -> 676 | E12: =MAX(0,B12-D12) -> 1103.11 | F12: 509.76 | H12: a spouse costs more than any number of children
A13: Emp. + Child | B13: 1609.32 | C13: 2 | D13: =$B$7*C13 -> 676 | E13: =MAX(0,B13-D13) -> 933.32 | F13: 509.76 | H13: ASSUMPTION — your policy did not name the child tiers
A14: Emp. + Children | B14: 1609.32 | C14: 2 | D14: =$B$7*C14 -> 676 | E14: =MAX(0,B14-D14) -> 933.32 | F14: 509.76 | H14: ASSUMPTION — priced the same as one child; Insperity charges the same
A15: Emp. + Family | B15: 2624.24 | C15: 3 | D15: =$B$7*C15 -> 1014 | E15: =MAX(0,B15-D15) -> 1610.24 | F15: 509.76
A17: 3. ELECTIONS BY EMPLOYEE
A18: Employee | B18: Tier # | C18: Employer medical /mo | D18: 401(k) eligible comp | E18: 401(k) match /mo | F18: Run-rate employer /mo | G18: 2026 average /mo (prorated)
A19: ='Staff P&L'!$A$6 -> Steven Nikolov | B19: 5 | C19: =IFERROR(INDEX($E$11:$E$15,B19),0) -> 1610.24 | D19: ='Staff P&L'!$E$6 -> 184500 | E19: =D19/12*$B$30*$B$31 -> 461.25 | F19: =C19+E19 -> 2071.49 | G19: =F19*$B$44/12 -> 345.24833
A20: ='Staff P&L'!$A$7 -> Lisa Danforth | B20: 5 | C20: =IFERROR(INDEX($E$11:$E$15,B20),0) -> 1610.24 | D20: ='Staff P&L'!$E$7 -> 176000 | E20: =D20/12*$B$30*$B$31 -> 440 | F20: =C20+E20 -> 2050.24 | G20: =F20*$B$44/12 -> 341.70667
A21: ='Staff P&L'!$A$8 -> Jessica Bumphus | B21: 2 | C21: =IFERROR(INDEX($E$11:$E$15,B21),0) -> 1103.11 | D21: ='Staff P&L'!$E$8 -> 125280 | E21: =D21/12*$B$30*$B$31 -> 313.2 | F21: =C21+E21 -> 1416.31 | G21: =F21*$B$44/12 -> 236.05167
A22: ='Staff P&L'!$A$9 -> Christine Johnson | B22: 1 | C22: =IFERROR(INDEX($E$11:$E$15,B22),0) -> 509.93 | D22: ='Staff P&L'!$E$9 -> 83520 | E22: =D22/12*$B$30*$B$31 -> 208.8 | F22: =C22+E22 -> 718.73 | G22: =F22*$B$44/12 -> 119.78833
A23: ='Staff P&L'!$A$10 -> Valentina Dikova | C23: 0 | D23: 0 | E23: 0 | F23: =C23+E23 -> 0 | G23: =F23*$B$44/12 -> 0 | H23: Bulgaria contractor — not on US benefits or the PEO
A24: ='Staff P&L'!$A$11 -> Josephine Mack | B24: 1 | C24: =IFERROR(INDEX($E$11:$E$15,B24),0) -> 509.93 | D24: ='Staff P&L'!$E$11 -> 80000 | E24: =D24/12*$B$30*$B$31 -> 200 | F24: =C24+E24 -> 709.93 | G24: =F24*$B$44/12 -> 118.32167
A25: TOTAL | C25: =SUM(C19:C24) -> 5343.45 | D25: =SUM(D19:D24) -> 649300 | E25: =SUM(E19:E24) -> 1623.25 | F25: =SUM(F19:F24) -> 6966.7 | G25: =SUM(G19:G24) -> 1161.1167 | H25: → column F feeds the PEO benefits column on Staff P&L
A26: Tier # key: 1 Employee Only · 2 Emp+Spouse · 3 Emp+Child · 4 Emp+Children · 5 Emp+Family
A27: ⚠ Tiers below are a GUESS that reproduces the proposal's census (2 family, 1 spouse, 2 employee-only). Set each person's real election.
A29: 4. 401(k) MATCH
A30: Employer match — % of eligible comp | B30: 0.03 | H30: You said start at 1–3%. Set it here; the sensitivity below prices each level.
A31: Participation assumption | B31: 1 | H31: Share of eligible employees who contribute enough to earn the full match. 100% is the conservative budget case.
A32: Annual match cost at the setting above | B32: =E25*12 -> 19479
A33: Sensitivity — annual cost at 1% / 2% / 3% | B33: =SUM(D19:D24)*0.01*$B$31 -> 6493 | C33: =SUM(D19:D24)*0.02*$B$31 -> 12986 | D33: =SUM(D19:D24)*0.03*$B$31 -> 19479 | H33: 1% · 2% · 3% of eligible W-2 comp
A35: 5. PEO SERVICE FEES (Insperity HR360)
A36: ⚠ Do NOT add Insperity's 8.00%-of-payroll payroll-tax allocation. The model already computes employer SS, Medicare, FUTA and AZ SUTA on the Assumptions tab, and does it more accurately because it respects each wage base.
A37: HR admin fee — per employee per month | B37: 183 | H37: Proposal: $183.00 per full-time employee per month
A38: Workers' comp & EPLI — % of payroll | B38: 0.0017 | H38: Proposal: 0.17% of gross payroll
A39: PEO payroll-tax load above the model's own — % of payroll | B39: 0.00233 | H39: Insperity allocates 8.00%; the model's own statutory calc is about 7.77%. Only the difference is incremental, so only the difference is charged here.
A40: W-2 employees enrolled | B40: =COUNT(B19:B24) -> 5
A41: US W-2 payroll subject to the fee | B41: =SUM(D19:D24)+'Staff P&L'!$H$25 -> 667005.6 | H41: base comp of W-2 staff plus W-2 bonuses
A42: One-time enrollment fee | B42: 2824.61
A43: First month the PEO is in effect (1 = Jan … 12 = Dec) | B43: 11 | H43: Anticipated start 25 Oct 2026, so November is the first full month — only 2 of 2026.
A44: Months of PEO in 2026 | B44: =MAX(0,13-$B$43) -> 2
A46: 6. EMPLOYER COST SUMMARY
...

Sheet Monthly Capacity
A1: Onyx Accounting Group, LLC
A2: Monthly Capacity — Working Days → Billable Hours → Revenue
A3: Real 2026 calendar drives the budget. Working days = weekdays − company holidays. Holidays are removed HERE, so never subtract them again downstream. Utilization is now per person, in column T.
B5: Jan 2026 | C5: Feb 2026 | D5: Mar 2026 | E5: Apr 2026 | F5: May 2026 | G5: Jun 2026 | H5: Jul 2026 | I5: Aug 2026 | J5: Sep 2026 | K5: Oct 2026 | L5: Nov 2026 | M5: Dec 2026 | N5: Total / Yr
A7: 1. CALENDAR
A8: Calendar days | B8: 31 | C8: 28 | D8: 31 | E8: 30 | F8: 31 | G8: 30 | H8: 31 | I8: 31 | J8: 30 | K8: 31 | L8: 30 | M8: 31 | N8: =SUM(B8:M8) -> 365
A9: Weekdays (Mon–Fri) | B9: 22 | C9: 20 | D9: 22 | E9: 22 | F9: 21 | G9: 22 | H9: 23 | I9: 21 | J9: 22 | K9: 22 | L9: 21 | M9: 23 | N9: =SUM(B9:M9) -> 261
A10: Company holidays | B10: 1 | C10: 0 | D10: 0 | E10: 0 | F10: 1 | G10: 0 | H10: 1 | I10: 0 | J10: 1 | K10: 0 | L10: 1 | M10: 2 | N10: =SUM(B10:M10) -> 7
A11: Working days | B11: =B9-B10 -> 21 | C11: =C9-C10 -> 20 | D11: =D9-D10 -> 22 | E11: =E9-E10 -> 22 | F11: =F9-F10 -> 20 | G11: =G9-G10 -> 22 | H11: =H9-H10 -> 22 | I11: =I9-I10 -> 21 | ... M11: =M9-M10 -> 21 | N11: =SUM(B11:M11) -> 254
A12: Hours per day | B12: 8 | C12: 8 | D12: 8 | E12: 8 | F12: 8 | G12: 8 | H12: 8 | I12: 8 | J12: 8 | K12: 8 | L12: 8 | M12: 8 | N12: =SUM(B12:M12) -> 96
A13: Gross working hrs / FTE | B13: =B11*B12 -> 168 | C13: =C11*C12 -> 160 | D13: =D11*D12 -> 176 | E13: =E11*E12 -> 176 | F13: =F11*F12 -> 160 | G13: =G11*G12 -> 176 | H13: =H11*H12 -> 176 | I13: =I11*I12 -> 168 | ... M13: =M11*M12 -> 168 | N13: =SUM(B13:M13) -> 2032
A14: Paid hrs / FTE (incl. holidays) | B14: =B9*B12 -> 176 | C14: =C9*C12 -> 160 | D14: =D9*D12 -> 176 | E14: =E9*E12 -> 176 | F14: =F9*F12 -> 168 | G14: =G9*G12 -> 176 | H14: =H9*H12 -> 184 | I14: =I9*I12 -> 168 | ... M14: =M9*M12 -> 184 | N14: =SUM(B14:M14) -> 2088 | P14: ← drives hourly pay & loaded-cost divisor
A16: 2. PTO SHAPING (per-person annual PTO hours are set in block 3)
A17: PTO distribution % of annual | B17: 0.083333333 | C17: 0.083333333 | D17: 0.083333333 | E17: 0.083333333 | F17: 0.083333333 | G17: 0.083333333 | H17: 0.083333333 | I17: 0.083333333 | J17: 0.083333333 | K17: 0.083333333 | L17: 0.083333333 | M17: 0.083333333 | N17: =SUM(B17:M17) -> 1 | P17: must total 100%
A18: Check: PTO distribution totals 100% | B18: =IF(ROUND(N17,6)=1,"OK","FIX — must total 100%") -> OK
A20: 3. BILLABLE HOURS BY PERSON
A21: Employee | B21: Jan | C21: Feb | D21: Mar | E21: Apr | F21: May | G21: Jun | H21: Jul | I21: Aug | J21: Sep | K21: Oct | L21: Nov | M21: Dec | N21: Total hrs | P21: Admin hrs /mo | Q21: Billable share % | R21: Annual PTO hrs | S21: Bill rate $/hr | T21: Utilization %
A22: ='Staff P&L'!$A$6 -> Steven Nikolov | B22: =IF(Assumptions!$B$38=2,B$75,MAX(0,(B$13-$P22-$R22*B$17))*$Q22*$T22) -> 73.406667 | C22: =IF(Assumptions!$B$38=2,C$75,MAX(0,(C$13-$P22-$R22*C$17))*$Q22*$T22) -> 69.766667 | D22: =IF(Assumptions!$B$38=2,D$75,MAX(0,(D$13-$P22-$R22*D$17))*$Q22*$T22) -> 77.046667 | E22: =IF(Assumptions!$B$38=2,E$75,MAX(0,(E$13-$P22-$R22*E$17))*$Q22*$T22) -> 77.046667 | F22: =IF(Assumptions!$B$38=2,F$75,MAX(0,(F$13-$P22-$R22*F$17))*$Q22*$T22) -> 69.766667 | G22: =IF(Assumptions!$B$38=2,G$75,MAX(0,(G$13-$P22-$R22*G$17))*$Q22*$T22) -> 77.046667 | H22: =IF(Assumptions!$B$38=2,H$75,MAX(0,(H$13-$P22-$R22*H$17))*$Q22*$T22) -> 77.046667 | I22: =IF(Assumptions!$B$38=2,I$75,MAX(0,(I$13-$P22-$R22*I$17))*$Q22*$T22) -> 73.406667 | ... M22: =IF(Assumptions!$B$38=2,M$75,MAX(0,(M$13-$P22-$R22*M$17))*$Q22*$T22) -> 73.406667 | N22: =SUM(B22:M22) -> 888.16 | P22: 0 | Q22: 0.5 | R22: 80 | S22: =Assumptions!$B$33 -> 246.57126 | T22: =Assumptions!$B$15 -> 0.91
A23: ='Staff P&L'!$A$7 -> Lisa Danforth | B23: =MAX(0,(B$13-$P23-$R23*B$17))*$Q23*$T23 -> 128.61333 | C23: =MAX(0,(C$13-$P23-$R23*C$17))*$Q23*$T23 -> 121.33333 | D23: =MAX(0,(D$13-$P23-$R23*D$17))*$Q23*$T23 -> 135.89333 | E23: =MAX(0,(E$13-$P23-$R23*E$17))*$Q23*$T23 -> 135.89333 | F23: =MAX(0,(F$13-$P23-$R23*F$17))*$Q23*$T23 -> 121.33333 | G23: =MAX(0,(G$13-$P23-$R23*G$17))*$Q23*$T23 -> 135.89333 | H23: =MAX(0,(H$13-$P23-$R23*H$17))*$Q23*$T23 -> 135.89333 | I23: =MAX(0,(I$13-$P23-$R23*I$17))*$Q23*$T23 -> 128.61333 | ... M23: =MAX(0,(M$13-$P23-$R23*M$17))*$Q23*$T23 -> 128.61333 | N23: =SUM(B23:M23) -> 1557.92 | P23: 20 | Q23: 1 | R23: 80 | S23: =Assumptions!$B$33 -> 246.57126 | T23: =Assumptions!$B$15 -> 0.91
A24: ='Staff P&L'!$A$8 -> Jessica Bumphus | B24: =MAX(0,(B$13-$P24-$R24*B$17))*$Q24*$T24 -> 128.61333 | C24: =MAX(0,(C$13-$P24-$R24*C$17))*$Q24*$T24 -> 121.33333 | D24: =MAX(0,(D$13-$P24-$R24*D$17))*$Q24*$T24 -> 135.89333 | E24: =MAX(0,(E$13-$P24-$R24*E$17))*$Q24*$T24 -> 135.89333 | F24: =MAX(0,(F$13-$P24-$R24*F$17))*$Q24*$T24 -> 121.33333 | G24: =MAX(0,(G$13-$P24-$R24*G$17))*$Q24*$T24 -> 135.89333 | H24: =MAX(0,(H$13-$P24-$R24*H$17))*$Q24*$T24 -> 135.89333 | I24: =MAX(0,(I$13-$P24-$R24*I$17))*$Q24*$T24 -> 128.61333 | ... M24: =MAX(0,(M$13-$P24-$R24*M$17))*$Q24*$T24 -> 128.61333 | N24: =SUM(B24:M24) -> 1557.92 | P24: 20 | Q24: 1 | R24: 80 | S24: =Assumptions!$B$34 -> 151.11296 | T24: =Assumptions!$B$15 -> 0.91
A25: ='Staff P&L'!$A$9 -> Christine Johnson | B25: =MAX(0,(B$13-$P25-$R25*B$17))*$Q25*$T25 -> 128.61333 | C25: =MAX(0,(C$13-$P25-$R25*C$17))*$Q25*$T25 -> 121.33333 | D25: =MAX(0,(D$13-$P25-$R25*D$17))*$Q25*$T25 -> 135.89333 | E25: =MAX(0,(E$13-$P25-$R25*E$17))*$Q25*$T25 -> 135.89333 | F25: =MAX(0,(F$13-$P25-$R25*F$17))*$Q25*$T25 -> 121.33333 | G25: =MAX(0,(G$13-$P25-$R25*G$17))*$Q25*$T25 -> 135.89333 | H25: =MAX(0,(H$13-$P25-$R25*H$17))*$Q25*$T25 -> 135.89333 | I25: =MAX(0,(I$13-$P25-$R25*I$17))*$Q25*$T25 -> 128.61333 | ... M25: =MAX(0,(M$13-$P25-$R25*M$17))*$Q25*$T25 -> 128.61333 | N25: =SUM(B25:M25) -> 1557.92 | P25: 20 | Q25: 1 | R25: 80 | S25: =Assumptions!$B$35 -> 94.988641 | T25: =Assumptions!$B$15 -> 0.91
A26: ='Staff P&L'!$A$10 -> Valentina Dikova | B26: =MAX(0,(B$13-$P26-$R26*B$17))*$Q26*$T26 -> 134.68 | C26: =MAX(0,(C$13-$P26-$R26*C$17))*$Q26*$T26 -> 127.4 | D26: =MAX(0,(D$13-$P26-$R26*D$17))*$Q26*$T26 -> 141.96 | E26: =MAX(0,(E$13-$P26-$R26*E$17))*$Q26*$T26 -> 141.96 | F26: =MAX(0,(F$13-$P26-$R26*F$17))*$Q26*$T26 -> 127.4 | G26: =MAX(0,(G$13-$P26-$R26*G$17))*$Q26*$T26 -> 141.96 | H26: =MAX(0,(H$13-$P26-$R26*H$17))*$Q26*$T26 -> 141.96 | I26: =MAX(0,(I$13-$P26-$R26*I$17))*$Q26*$T26 -> 134.68 | ... M26: =MAX(0,(M$13-$P26-$R26*M$17))*$Q26*$T26 -> 134.68 | N26: =SUM(B26:M26) -> 1630.72 | P26: 20 | Q26: 1 | R26: 0 | S26: =Assumptions!$B$35 -> 94.988641 | T26: =Assumptions!$B$15 -> 0.91
A27: ='Staff P&L'!$A$11 -> Josephine Mack | B27: =MAX(0,(B$13-$P27-$R27*B$17))*$Q27*$T27 -> 22.022 | C27: =MAX(0,(C$13-$P27-$R27*C$17))*$Q27*$T27 -> 20.93 | D27: =MAX(0,(D$13-$P27-$R27*D$17))*$Q27*$T27 -> 23.114 | E27: =MAX(0,(E$13-$P27-$R27*E$17))*$Q27*$T27 -> 23.114 | F27: =MAX(0,(F$13-$P27-$R27*F$17))*$Q27*$T27 -> 20.93 | G27: =MAX(0,(G$13-$P27-$R27*G$17))*$Q27*$T27 -> 23.114 | H27: =MAX(0,(H$13-$P27-$R27*H$17))*$Q27*$T27 -> 23.114 | I27: =MAX(0,(I$13-$P27-$R27*I$17))*$Q27*$T27 -> 22.022 | ... M27: =MAX(0,(M$13-$P27-$R27*M$17))*$Q27*$T27 -> 22.022 | N27: =SUM(B27:M27) -> 266.448 | P27: 0 | Q27: 0.15 | R27: 80 | S27: =Assumptions!$B$35 -> 94.988641 | T27: =Assumptions!$B$15 -> 0.91
A28: Total billable hours | B28: =SUM(B22:B27) -> 615.94867 | C28: =SUM(C22:C27) -> 582.09667 | D28: =SUM(D22:D27) -> 649.80067 | E28: =SUM(E22:E27) -> 649.80067 | F28: =SUM(F22:F27) -> 582.09667 | G28: =SUM(G22:G27) -> 649.80067 | H28: =SUM(H22:H27) -> 649.80067 | I28: =SUM(I22:I27) -> 615.94867 | ... N28: =SUM(N22:N27) -> 7459.088 | P28: weighted avg util → | Q28: =IFERROR(SUMPRODUCT($N$22:$N$27)/SUMPRODUCT(($N$22:$N$27)/$T$22:$T$27),0) -> 0.91
A30: 4. REVENUE BY PERSON (billable hours × bill rate)
A31: ='Staff P&L'!$A$6 -> Steven Nikolov | B31: =B22*$S22 -> 18099.974 | C31: =C22*$S22 -> 17202.455 | D31: =D22*$S22 -> 18997.493 | E31: =E22*$S22 -> 18997.493 | F31: =F22*$S22 -> 17202.455 | G31: =G22*$S22 -> 18997.493 | H31: =H22*$S22 -> 18997.493 | I31: =I22*$S22 -> 18099.974 | ... M31: =M22*$S22 -> 18099.974 | N31: =SUM(B31:M31) -> 218994.73
A32: ='Staff P&L'!$A$7 -> Lisa Danforth | B32: =B23*$S23 -> 31712.351 | C32: =C23*$S23 -> 29917.313 | D32: =D23*$S23 -> 33507.39 | E32: =E23*$S23 -> 33507.39 | F32: =F23*$S23 -> 29917.313 | G32: =G23*$S23 -> 33507.39 | H32: =H23*$S23 -> 33507.39 | I32: =I23*$S23 -> 31712.351 | ... M32: =M23*$S23 -> 31712.351 | N32: =SUM(B32:M32) -> 384138.29
A33: ='Staff P&L'!$A$8 -> Jessica Bumphus | B33: =B24*$S24 -> 19435.141 | C33: =C24*$S24 -> 18335.039 | D33: =D24*$S24 -> 20535.243 | E33: =E24*$S24 -> 20535.243 | F33: =F24*$S24 -> 18335.039 | G33: =G24*$S24 -> 20535.243 | H33: =H24*$S24 -> 20535.243 | I33: =I24*$S24 -> 19435.141 | ... M33: =M24*$S24 -> 19435.141 | N33: =SUM(B33:M33) -> 235421.9
A34: ='Staff P&L'!$A$9 -> Christine Johnson | B34: =B25*$S25 -> 12216.806 | C34: =C25*$S25 -> 11525.288 | D34: =D25*$S25 -> 12908.323 | E34: =E25*$S25 -> 12908.323 | F34: =F25*$S25 -> 11525.288 | G34: =G25*$S25 -> 12908.323 | H34: =H25*$S25 -> 12908.323 | I34: =I25*$S25 -> 12216.806 | ... M34: =M25*$S25 -> 12216.806 | N34: =SUM(B34:M34) -> 147984.7
A35: ='Staff P&L'!$A$10 -> Valentina Dikova | B35: =B26*$S26 -> 12793.07 | C35: =C26*$S26 -> 12101.553 | D35: =D26*$S26 -> 13484.588 | E35: =E26*$S26 -> 13484.588 | F35: =F26*$S26 -> 12101.553 | G35: =G26*$S26 -> 13484.588 | H35: =H26*$S26 -> 13484.588 | I35: =I26*$S26 -> 12793.07 | ... M35: =M26*$S26 -> 12793.07 | N35: =SUM(B35:M35) -> 154899.88
A36: ='Staff P&L'!$A$11 -> Josephine Mack | B36: =B27*$S27 -> 2091.8399 | C36: =C27*$S27 -> 1988.1123 | D36: =D27*$S27 -> 2195.5675 | E36: =E27*$S27 -> 2195.5675 | F36: =F27*$S27 -> 1988.1123 | G36: =G27*$S27 -> 2195.5675 | H36: =H27*$S27 -> 2195.5675 | I36: =I27*$S27 -> 2091.8399 | ... M36: =M27*$S27 -> 2091.8399 | N36: =SUM(B36:M36) -> 25309.534
A37: TOTAL REVENUE → Budget P&L | B37: =SUM(B31:B36) -> 96349.182 | C37: =SUM(C31:C36) -> 91069.76 | D37: =SUM(D31:D36) -> 101628.6 | E37: =SUM(E31:E36) -> 101628.6 | F37: =SUM(F31:F36) -> 91069.76 | G37: =SUM(G31:G36) -> 101628.6 | H37: =SUM(H31:H36) -> 101628.6 | I37: =SUM(I31:I36) -> 96349.182 | ... N37: =SUM(N31:N36) -> 1166749
A39: 5. HOURLY-STAFF WAGE COST (paid hours × pay rate)
A40: ='Staff P&L'!$A$8 -> Jessica Bumphus | B40: =B14*'Staff P&L'!$D$8 -> 10560 | C40: =C14*'Staff P&L'!$D$8 -> 9600 | D40: =D14*'Staff P&L'!$D$8 -> 10560 | E40: =E14*'Staff P&L'!$D$8 -> 10560 | F40: =F14*'Staff P&L'!$D$8 -> 10080 | G40: =G14*'Staff P&L'!$D$8 -> 10560 | H40: =H14*'Staff P&L'!$D$8 -> 11040 | I40: =I14*'Staff P&L'!$D$8 -> 10080 | ... M40: =M14*'Staff P&L'!$D$8 -> 11040 | N40: =SUM(B40:M40) -> 125280 | P40: paid hrs incl. holidays × $/hr
A41: ='Staff P&L'!$A$9 -> Christine Johnson | B41: =B14*'Staff P&L'!$D$9 -> 7040 | C41: =C14*'Staff P&L'!$D$9 -> 6400 | D41: =D14*'Staff P&L'!$D$9 -> 7040 | E41: =E14*'Staff P&L'!$D$9 -> 7040 | F41: =F14*'Staff P&L'!$D$9 -> 6720 | G41: =G14*'Staff P&L'!$D$9 -> 7040 | H41: =H14*'Staff P&L'!$D$9 -> 7360 | I41: =I14*'Staff P&L'!$D$9 -> 6720 | ... M41: =M14*'Staff P&L'!$D$9 -> 7360 | N41: =SUM(B41:M41) -> 83520
A42: Total hourly wages | B42: =SUM(B40:B41) -> 17600 | C42: =SUM(C40:C41) -> 16000 | D42: =SUM(D40:D41) -> 17600 | E42: =SUM(E40:E41) -> 17600 | F42: =SUM(F40:F41) -> 16800 | G42: =SUM(G40:G41) -> 17600 | H42: =SUM(H40:H41) -> 18400 | I42: =SUM(I40:I41) -> 16800 | ... N42: =SUM(N40:N41) -> 208800
A44: • Working days = weekdays − company holidays (7/yr per the Onyx Handbook). Holidays are already excluded here, so the model must NOT deduct them again downstream.
A45: • Billable hours = (gross working hrs − admin hrs − PTO for the month) × billable share × utilization (Assumptions!B15).
A46: • Paid hours include holidays because the handbook pays them; that is the divisor for hourly wages and loaded cost per hour.
A47: • 2026 has 254 working days / 2,032 working hours and 261 weekdays / 2,088 paid hours per FTE.
...

Sheet Growth & Hiring
A1: Onyx Accounting Group, LLC
A2: Growth & Hiring — client wins and added staff for the rest of 2026
A3: Everything here is incremental to the base plan. It flows into the Budget P&L, and therefore into the Aug–Dec months of Forecast 2026. The Jan–Jul actuals never move.
B5: Jan 2026 | C5: Feb 2026 | D5: Mar 2026 | E5: Apr 2026 | F5: May 2026 | G5: Jun 2026 | H5: Jul 2026 | I5: Aug 2026 | J5: Sep 2026 | K5: Oct 2026 | L5: Nov 2026 | M5: Dec 2026 | N5: Total
A7: 1. NEW CLIENT REVENUE
A8: New recurring revenue won in the month | B8: 0 | C8: 0 | D8: 0 | E8: 0 | F8: 0 | G8: 0 | H8: 0 | I8: 3000 | J8: 3000 | K8: 3000 | L8: 3000 | M8: 3000 | N8: =SUM(B8:M8) -> 15000 | P8: monthly fee added that month
A9: Cumulative new recurring revenue | B9: =0+B8 -> 0 | C9: =B9+C8 -> 0 | D9: =C9+D8 -> 0 | E9: =D9+E8 -> 0 | F9: =E9+F8 -> 0 | G9: =F9+G8 -> 0 | H9: =G9+H8 -> 0 | I9: =H9+I8 -> 3000 | J9: =I9+J8 -> 6000 | ... M9: =L9+M8 -> 15000 | N9: =SUM(B9:M9) -> 45000 | P9: ← this is the revenue that reaches the P&L
A10: One-off / project revenue | B10: 0 | C10: 0 | D10: 0 | E10: 0 | F10: 0 | G10: 0 | H10: 0 | I10: 0 | J10: 0 | K10: 0 | L10: 0 | M10: 0 | N10: =SUM(B10:M10) -> 0 | P10: clean-ups, implementations — not recurring
A11: TOTAL INCREMENTAL REVENUE | B11: =B9+B10 -> 0 | C11: =C9+C10 -> 0 | D11: =D9+D10 -> 0 | E11: =E9+E10 -> 0 | F11: =F9+F10 -> 0 | G11: =G9+G10 -> 0 | H11: =H9+H10 -> 0 | I11: =I9+I10 -> 3000 | ... N11: =N9+N10 -> 45000
A13: 2. NEW HIRES
A14: Hire (cost by month) | B14: Jan | C14: Feb | D14: Mar | E14: Apr | F14: May | G14: Jun | H14: Jul | I14: Aug | J14: Sep | K14: Oct | L14: Nov | M14: Dec | N14: Total cost | P14: Annual pay | Q14: Start month | R14: Billable share | S14: Utilization | T14: Bill rate $/hr
A15: Staff accountant #1 | B15: =IF(OR($Q15=0,1<$Q15),0,$P15/12*(1+Assumptions!$B$21+Assumptions!$B$19)) -> 0 | C15: =IF(OR($Q15=0,2<$Q15),0,$P15/12*(1+Assumptions!$B$21+Assumptions!$B$19)) -> 0 | D15: =IF(OR($Q15=0,3<$Q15),0,$P15/12*(1+Assumptions!$B$21+Assumptions!$B$19)) -> 0 | E15: =IF(OR($Q15=0,4<$Q15),0,$P15/12*(1+Assumptions!$B$21+Assumptions!$B$19)) -> 0 | F15: =IF(OR($Q15=0,5<$Q15),0,$P15/12*(1+Assumptions!$B$21+Assumptions!$B$19)) -> 0 | G15: =IF(OR($Q15=0,6<$Q15),0,$P15/12*(1+Assumptions!$B$21+Assumptions!$B$19)) -> 0 | H15: =IF(OR($Q15=0,7<$Q15),0,$P15/12*(1+Assumptions!$B$21+Assumptions!$B$19)) -> 0 | I15: =IF(OR($Q15=0,8<$Q15),0,$P15/12*(1+Assumptions!$B$21+Assumptions!$B$19)) -> 0 | J15: =IF(OR($Q15=0,9<$Q15),0,$P15/12*(1+Assumptions!$B$21+Assumptions!$B$19)) -> 0 | K15: =IF(OR($Q15=0,10<$Q15),0,$P15/12*(1+Assumptions!$B$21+Assumptions!$B$19)) -> 7625.2083 | L15: =IF(OR($Q15=0,11<$Q15),0,$P15/12*(1+Assumptions!$B$21+Assumptions!$B$19)) -> 7625.2083 | M15: =IF(OR($Q15=0,12<$Q15),0,$P15/12*(1+Assumptions!$B$21+Assumptions!$B$19)) -> 7625.2083 | N15: =SUM(B15:M15) -> 22875.625 | P15: 85000 | Q15: 10 | R15: 1 | S15: 0.85 | T15: =Assumptions!$B$35 -> 94.988641 | U15: start month 0 = not hired
A16: Staff accountant #2 | B16: =IF(OR($Q16=0,1<$Q16),0,$P16/12*(1+Assumptions!$B$21+Assumptions!$B$19)) -> 0 | C16: =IF(OR($Q16=0,2<$Q16),0,$P16/12*(1+Assumptions!$B$21+Assumptions!$B$19)) -> 0 | D16: =IF(OR($Q16=0,3<$Q16),0,$P16/12*(1+Assumptions!$B$21+Assumptions!$B$19)) -> 0 | E16: =IF(OR($Q16=0,4<$Q16),0,$P16/12*(1+Assumptions!$B$21+Assumptions!$B$19)) -> 0 | F16: =IF(OR($Q16=0,5<$Q16),0,$P16/12*(1+Assumptions!$B$21+Assumptions!$B$19)) -> 0 | G16: =IF(OR($Q16=0,6<$Q16),0,$P16/12*(1+Assumptions!$B$21+Assumptions!$B$19)) -> 0 | H16: =IF(OR($Q16=0,7<$Q16),0,$P16/12*(1+Assumptions!$B$21+Assumptions!$B$19)) -> 0 | I16: =IF(OR($Q16=0,8<$Q16),0,$P16/12*(1+Assumptions!$B$21+Assumptions!$B$19)) -> 0 | J16: =IF(OR($Q16=0,9<$Q16),0,$P16/12*(1+Assumptions!$B$21+Assumptions!$B$19)) -> 0 | K16: =IF(OR($Q16=0,10<$Q16),0,$P16/12*(1+Assumptions!$B$21+Assumptions!$B$19)) -> 0 | L16: =IF(OR($Q16=0,11<$Q16),0,$P16/12*(1+Assumptions!$B$21+Assumptions!$B$19)) -> 0 | M16: =IF(OR($Q16=0,12<$Q16),0,$P16/12*(1+Assumptions!$B$21+Assumptions!$B$19)) -> 0 | N16: =SUM(B16:M16) -> 0 | P16: 85000 | Q16: 0 | R16: 1 | S16: 0.85 | T16: =Assumptions!$B$35 -> 94.988641 | U16: start month 0 = not hired
A17: Controller #2 | B17: =IF(OR($Q17=0,1<$Q17),0,$P17/12*(1+Assumptions!$B$21+Assumptions!$B$19)) -> 0 | C17: =IF(OR($Q17=0,2<$Q17),0,$P17/12*(1+Assumptions!$B$21+Assumptions!$B$19)) -> 0 | D17: =IF(OR($Q17=0,3<$Q17),0,$P17/12*(1+Assumptions!$B$21+Assumptions!$B$19)) -> 0 | E17: =IF(OR($Q17=0,4<$Q17),0,$P17/12*(1+Assumptions!$B$21+Assumptions!$B$19)) -> 0 | F17: =IF(OR($Q17=0,5<$Q17),0,$P17/12*(1+Assumptions!$B$21+Assumptions!$B$19)) -> 0 | G17: =IF(OR($Q17=0,6<$Q17),0,$P17/12*(1+Assumptions!$B$21+Assumptions!$B$19)) -> 0 | H17: =IF(OR($Q17=0,7<$Q17),0,$P17/12*(1+Assumptions!$B$21+Assumptions!$B$19)) -> 0 | I17: =IF(OR($Q17=0,8<$Q17),0,$P17/12*(1+Assumptions!$B$21+Assumptions!$B$19)) -> 0 | J17: =IF(OR($Q17=0,9<$Q17),0,$P17/12*(1+Assumptions!$B$21+Assumptions!$B$19)) -> 0 | K17: =IF(OR($Q17=0,10<$Q17),0,$P17/12*(1+Assumptions!$B$21+Assumptions!$B$19)) -> 0 | L17: =IF(OR($Q17=0,11<$Q17),0,$P17/12*(1+Assumptions!$B$21+Assumptions!$B$19)) -> 0 | M17: =IF(OR($Q17=0,12<$Q17),0,$P17/12*(1+Assumptions!$B$21+Assumptions!$B$19)) -> 0 | N17: =SUM(B17:M17) -> 0 | P17: 125000 | Q17: 0 | R17: 1 | S17: 0.85 | T17: =Assumptions!$B$34 -> 151.11296 | U17: start month 0 = not hired
A18: Total new-hire cost | B18: =SUM(B15:B17) -> 0 | C18: =SUM(C15:C17) -> 0 | D18: =SUM(D15:D17) -> 0 | E18: =SUM(E15:E17) -> 0 | F18: =SUM(F15:F17) -> 0 | G18: =SUM(G15:G17) -> 0 | H18: =SUM(H15:H17) -> 0 | I18: =SUM(I15:I17) -> 0 | ... N18: =SUM(N15:N17) -> 22875.625
A19: New-hire billable hours | B19: =IF(OR($Q15=0,1<$Q15),0,MAX(0,('Monthly Capacity'!B$13-20-80*'Monthly Capacity'!B$17))*$R15*$S15)+IF(OR($Q16=0,1<$Q16),0,MAX(0,('Monthly Capacity'!B$13-20-80*'Monthly Capacity'!B$17))*$R16*$S16)+IF(OR($Q17=0,1<$Q17),0,MAX(0,('Monthly Capacity'!B$13-20-80*'Monthly Capacity'!B$17))*$R17*$S17) -> 0 | C19: =IF(OR($Q15=0,2<$Q15),0,MAX(0,('Monthly Capacity'!C$13-20-80*'Monthly Capacity'!C$17))*$R15*$S15)+IF(OR($Q16=0,2<$Q16),0,MAX(0,('Monthly Capacity'!C$13-20-80*'Monthly Capacity'!C$17))*$R16*$S16)+IF(OR($Q17=0,2<$Q17),0,MAX(0,('Monthly Capacity'!C$13-20-80*'Monthly Capacity'!C$17))*$R17*$S17) -> 0 | D19: =IF(OR($Q15=0,3<$Q15),0,MAX(0,('Monthly Capacity'!D$13-20-80*'Monthly Capacity'!D$17))*$R15*$S15)+IF(OR($Q16=0,3<$Q16),0,MAX(0,('Monthly Capacity'!D$13-20-80*'Monthly Capacity'!D$17))*$R16*$S16)+IF(OR($Q17=0,3<$Q17),0,MAX(0,('Monthly Capacity'!D$13-20-80*'Monthly Capacity'!D$17))*$R17*$S17) -> 0 | E19: =IF(OR($Q15=0,4<$Q15),0,MAX(0,('Monthly Capacity'!E$13-20-80*'Monthly Capacity'!E$17))*$R15*$S15)+IF(OR($Q16=0,4<$Q16),0,MAX(0,('Monthly Capacity'!E$13-20-80*'Monthly Capacity'!E$17))*$R16*$S16)+IF(OR($Q17=0,4<$Q17),0,MAX(0,('Monthly Capacity'!E$13-20-80*'Monthly Capacity'!E$17))*$R17*$S17) -> 0 | F19: =IF(OR($Q15=0,5<$Q15),0,MAX(0,('Monthly Capacity'!F$13-20-80*'Monthly Capacity'!F$17))*$R15*$S15)+IF(OR($Q16=0,5<$Q16),0,MAX(0,('Monthly Capacity'!F$13-20-80*'Monthly Capacity'!F$17))*$R16*$S16)+IF(OR($Q17=0,5<$Q17),0,MAX(0,('Monthly Capacity'!F$13-20-80*'Monthly Capacity'!F$17))*$R17*$S17) -> 0 | G19: =IF(OR($Q15=0,6<$Q15),0,MAX(0,('Monthly Capacity'!G$13-20-80*'Monthly Capacity'!G$17))*$R15*$S15)+IF(OR($Q16=0,6<$Q16),0,MAX(0,('Monthly Capacity'!G$13-20-80*'Monthly Capacity'!G$17))*$R16*$S16)+IF(OR($Q17=0,6<$Q17),0,MAX(0,('Monthly Capacity'!G$13-20-80*'Monthly Capacity'!G$17))*$R17*$S17) -> 0 | H19: =IF(OR($Q15=0,7<$Q15),0,MAX(0,('Monthly Capacity'!H$13-20-80*'Monthly Capacity'!H$17))*$R15*$S15)+IF(OR($Q16=0,7<$Q16),0,MAX(0,('Monthly Capacity'!H$13-20-80*'Monthly Capacity'!H$17))*$R16*$S16)+IF(OR($Q17=0,7<$Q17),0,MAX(0,('Monthly Capacity'!H$13-20-80*'Monthly Capacity'!H$17))*$R17*$S17) -> 0 | I19: =IF(OR($Q15=0,8<$Q15),0,MAX(0,('Monthly Capacity'!I$13-20-80*'Monthly Capacity'!I$17))*$R15*$S15)+IF(OR($Q16=0,8<$Q16),0,MAX(0,('Monthly Capacity'!I$13-20-80*'Monthly Capacity'!I$17))*$R16*$S16)+IF(OR($Q17=0,8<$Q17),0,MAX(0,('Monthly Capacity'!I$13-20-80*'Monthly Capacity'!I$17))*$R17*$S17) -> 0 | J19: =IF(OR($Q15=0,9<$Q15),0,MAX(0,('Monthly Capacity'!J$13-20-80*'Monthly Capacity'!J$17))*$R15*$S15)+IF(OR($Q16=0,9<$Q16),0,MAX(0,('Monthly Capacity'!J$13-20-80*'Monthly Capacity'!J$17))*$R16*$S16)+IF(OR($Q17=0,9<$Q17),0,MAX(0,('Monthly Capacity'!J$13-20-80*'Monthly Capacity'!J$17))*$R17*$S17) -> 0 | K19: =IF(OR($Q15=0,10<$Q15),0,MAX(0,('Monthly Capacity'!K$13-20-80*'Monthly Capacity'!K$17))*$R15*$S15)+IF(OR($Q16=0,10<$Q16),0,MAX(0,('Monthly Capacity'!K$13-20-80*'Monthly Capacity'!K$17))*$R16*$S16)+IF(OR($Q17=0,10<$Q17),0,MAX(0,('Monthly Capacity'!K$13-20-80*'Monthly Capacity'!K$17))*$R17*$S17) -> 126.93333 | L19: =IF(OR($Q15=0,11<$Q15),0,MAX(0,('Monthly Capacity'!L$13-20-80*'Monthly Capacity'!L$17))*$R15*$S15)+IF(OR($Q16=0,11<$Q16),0,MAX(0,('Monthly Capacity'!L$13-20-80*'Monthly Capacity'!L$17))*$R16*$S16)+IF(OR($Q17=0,11<$Q17),0,MAX(0,('Monthly Capacity'!L$13-20-80*'Monthly Capacity'!L$17))*$R17*$S17) -> 113.33333 | M19: =IF(OR($Q15=0,12<$Q15),0,MAX(0,('Monthly Capacity'!M$13-20-80*'Monthly Capacity'!M$17))*$R15*$S15)+IF(OR($Q16=0,12<$Q16),0,MAX(0,('Monthly Capacity'!M$13-20-80*'Monthly Capacity'!M$17))*$R16*$S16)+IF(OR($Q17=0,12<$Q17),0,MAX(0,('Monthly Capacity'!M$13-20-80*'Monthly Capacity'!M$17))*$R17*$S17) -> 120.13333 | N19: =SUM(B19:M19) -> 360.4
A20: New-hire revenue | B20: =IF(OR($Q15=0,1<$Q15),0,MAX(0,('Monthly Capacity'!B$13-20-80*'Monthly Capacity'!B$17))*$R15*$S15*$T15)+IF(OR($Q16=0,1<$Q16),0,MAX(0,('Monthly Capacity'!B$13-20-80*'Monthly Capacity'!B$17))*$R16*$S16*$T16)+IF(OR($Q17=0,1<$Q17),0,MAX(0,('Monthly Capacity'!B$13-20-80*'Monthly Capacity'!B$17))*$R17*$S17*$T17) -> 0 | C20: =IF(OR($Q15=0,2<$Q15),0,MAX(0,('Monthly Capacity'!C$13-20-80*'Monthly Capacity'!C$17))*$R15*$S15*$T15)+IF(OR($Q16=0,2<$Q16),0,MAX(0,('Monthly Capacity'!C$13-20-80*'Monthly Capacity'!C$17))*$R16*$S16*$T16)+IF(OR($Q17=0,2<$Q17),0,MAX(0,('Monthly Capacity'!C$13-20-80*'Monthly Capacity'!C$17))*$R17*$S17*$T17) -> 0 | D20: =IF(OR($Q15=0,3<$Q15),0,MAX(0,('Monthly Capacity'!D$13-20-80*'Monthly Capacity'!D$17))*$R15*$S15*$T15)+IF(OR($Q16=0,3<$Q16),0,MAX(0,('Monthly Capacity'!D$13-20-80*'Monthly Capacity'!D$17))*$R16*$S16*$T16)+IF(OR($Q17=0,3<$Q17),0,MAX(0,('Monthly Capacity'!D$13-20-80*'Monthly Capacity'!D$17))*$R17*$S17*$T17) -> 0 | E20: =IF(OR($Q15=0,4<$Q15),0,MAX(0,('Monthly Capacity'!E$13-20-80*'Monthly Capacity'!E$17))*$R15*$S15*$T15)+IF(OR($Q16=0,4<$Q16),0,MAX(0,('Monthly Capacity'!E$13-20-80*'Monthly Capacity'!E$17))*$R16*$S16*$T16)+IF(OR($Q17=0,4<$Q17),0,MAX(0,('Monthly Capacity'!E$13-20-80*'Monthly Capacity'!E$17))*$R17*$S17*$T17) -> 0 | F20: =IF(OR($Q15=0,5<$Q15),0,MAX(0,('Monthly Capacity'!F$13-20-80*'Monthly Capacity'!F$17))*$R15*$S15*$T15)+IF(OR($Q16=0,5<$Q16),0,MAX(0,('Monthly Capacity'!F$13-20-80*'Monthly Capacity'!F$17))*$R16*$S16*$T16)+IF(OR($Q17=0,5<$Q17),0,MAX(0,('Monthly Capacity'!F$13-20-80*'Monthly Capacity'!F$17))*$R17*$S17*$T17) -> 0 | G20: =IF(OR($Q15=0,6<$Q15),0,MAX(0,('Monthly Capacity'!G$13-20-80*'Monthly Capacity'!G$17))*$R15*$S15*$T15)+IF(OR($Q16=0,6<$Q16),0,MAX(0,('Monthly Capacity'!G$13-20-80*'Monthly Capacity'!G$17))*$R16*$S16*$T16)+IF(OR($Q17=0,6<$Q17),0,MAX(0,('Monthly Capacity'!G$13-20-80*'Monthly Capacity'!G$17))*$R17*$S17*$T17) -> 0 | H20: =IF(OR($Q15=0,7<$Q15),0,MAX(0,('Monthly Capacity'!H$13-20-80*'Monthly Capacity'!H$17))*$R15*$S15*$T15)+IF(OR($Q16=0,7<$Q16),0,MAX(0,('Monthly Capacity'!H$13-20-80*'Monthly Capacity'!H$17))*$R16*$S16*$T16)+IF(OR($Q17=0,7<$Q17),0,MAX(0,('Monthly Capacity'!H$13-20-80*'Monthly Capacity'!H$17))*$R17*$S17*$T17) -> 0 | I20: =IF(OR($Q15=0,8<$Q15),0,MAX(0,('Monthly Capacity'!I$13-20-80*'Monthly Capacity'!I$17))*$R15*$S15*$T15)+IF(OR($Q16=0,8<$Q16),0,MAX(0,('Monthly Capacity'!I$13-20-80*'Monthly Capacity'!I$17))*$R16*$S16*$T16)+IF(OR($Q17=0,8<$Q17),0,MAX(0,('Monthly Capacity'!I$13-20-80*'Monthly Capacity'!I$17))*$R17*$S17*$T17) -> 0 | J20: =IF(OR($Q15=0,9<$Q15),0,MAX(0,('Monthly Capacity'!J$13-20-80*'Monthly Capacity'!J$17))*$R15*$S15*$T15)+IF(OR($Q16=0,9<$Q16),0,MAX(0,('Monthly Capacity'!J$13-20-80*'Monthly Capacity'!J$17))*$R16*$S16*$T16)+IF(OR($Q17=0,9<$Q17),0,MAX(0,('Monthly Capacity'!J$13-20-80*'Monthly Capacity'!J$17))*$R17*$S17*$T17) -> 0 | K20: =IF(OR($Q15=0,10<$Q15),0,MAX(0,('Monthly Capacity'!K$13-20-80*'Monthly Capacity'!K$17))*$R15*$S15*$T15)+IF(OR($Q16=0,10<$Q16),0,MAX(0,('Monthly Capacity'!K$13-20-80*'Monthly Capacity'!K$17))*$R16*$S16*$T16)+IF(OR($Q17=0,10<$Q17),0,MAX(0,('Monthly Capacity'!K$13-20-80*'Monthly Capacity'!K$17))*$R17*$S17*$T17) -> 12057.225 | L20: =IF(OR($Q15=0,11<$Q15),0,MAX(0,('Monthly Capacity'!L$13-20-80*'Monthly Capacity'!L$17))*$R15*$S15*$T15)+IF(OR($Q16=0,11<$Q16),0,MAX(0,('Monthly Capacity'!L$13-20-80*'Monthly Capacity'!L$17))*$R16*$S16*$T16)+IF(OR($Q17=0,11<$Q17),0,MAX(0,('Monthly Capacity'!L$13-20-80*'Monthly Capacity'!L$17))*$R17*$S17*$T17) -> 10765.379 | M20: =IF(OR($Q15=0,12<$Q15),0,MAX(0,('Monthly Capacity'!M$13-20-80*'Monthly Capacity'!M$17))*$R15*$S15*$T15)+IF(OR($Q16=0,12<$Q16),0,MAX(0,('Monthly Capacity'!M$13-20-80*'Monthly Capacity'!M$17))*$R16*$S16*$T16)+IF(OR($Q17=0,12<$Q17),0,MAX(0,('Monthly Capacity'!M$13-20-80*'Monthly Capacity'!M$17))*$R17*$S17*$T17) -> 11411.302 | N20: =SUM(B20:M20) -> 34233.906
A22: 3. NET IMPACT
A23: Incremental revenue — clients + new hires | B23: =B11+B20 -> 0 | C23: =C11+C20 -> 0 | D23: =D11+D20 -> 0 | E23: =E11+E20 -> 0 | F23: =F11+F20 -> 0 | G23: =G11+G20 -> 0 | H23: =H11+H20 -> 0 | I23: =I11+I20 -> 3000 | ... N23: =N11+N20 -> 79233.906
A24: Incremental cost — new hires | B24: =B18 -> 0 | C24: =C18 -> 0 | D24: =D18 -> 0 | E24: =E18 -> 0 | F24: =F18 -> 0 | G24: =G18 -> 0 | H24: =H18 -> 0 | I24: =I18 -> 0 | ... N24: =N18 -> 22875.625
A25: NET IMPACT ON NET INCOME | B25: =B23-B24 -> 0 | C25: =C23-C24 -> 0 | D25: =D23-D24 -> 0 | E25: =E23-E24 -> 0 | F25: =F23-F24 -> 0 | G25: =G23-G24 -> 0 | H25: =H23-H24 -> 0 | I25: =I23-I24 -> 3000 | ... N25: =N23-N24 -> 56358.281
A27: • New client revenue is entered as the monthly fee won in that month, then carried forward — a $3,000 client won in August bills $3,000 every month from August on.
A28: • A new hire's capacity uses the same calendar as everyone else: that month's working hours less 20 admin hours and their share of 80 hours PTO, times their billable share and utilization. New hires are assumed to ramp at 85%, not 91%.
A29: • Only the recurring and one-off revenue lines and the hire costs are inputs. Everything else is calculated, and the whole block adds to the Budget P&L, so Forecast 2026 picks it up in August through December.
A30: • New hires here do NOT carry benefits or PEO fees. Add them on the Benefits tab once a hire is real.

Sheet Budget P&L
A1: Onyx Accounting Group, LLC
A2: Budget — Profit and Loss (QuickBooks format)
A3: January–December 2026 (Forecast)
A4: Revenue and hourly wages follow the real 2026 working-day calendar (Monthly Capacity tab). Green = linked; blue = input.
B6: Jan 2026 | C6: Feb 2026 | D6: Mar 2026 | E6: Apr 2026 | F6: May 2026 | G6: Jun 2026 | H6: Jul 2026 | I6: Aug 2026 | J6: Sep 2026 | K6: Oct 2026 | L6: Nov 2026 | M6: Dec 2026 | N6: Total
A7: Income
A8: Billable Expense Income | B8: 0 | C8: 0 | D8: 0 | E8: 0 | F8: 0 | G8: 0 | H8: 0 | I8: 0 | J8: 0 | K8: 0 | L8: 0 | M8: 0 | N8: =SUM(B8:M8) -> 0 | P8: Reimbursed client expenses — input
A9: Sales | B9: ='Monthly Capacity'!B$37+'Growth & Hiring'!B$23 -> 96349.182 | C9: ='Monthly Capacity'!C$37+'Growth & Hiring'!C$23 -> 91069.76 | D9: ='Monthly Capacity'!D$37+'Growth & Hiring'!D$23 -> 101628.6 | E9: ='Monthly Capacity'!E$37+'Growth & Hiring'!E$23 -> 101628.6 | F9: ='Monthly Capacity'!F$37+'Growth & Hiring'!F$23 -> 91069.76 | G9: ='Monthly Capacity'!G$37+'Growth & Hiring'!G$23 -> 101628.6 | H9: ='Monthly Capacity'!H$37+'Growth & Hiring'!H$23 -> 101628.6 | I9: ='Monthly Capacity'!I$37+'Growth & Hiring'!I$23 -> 99349.182 | ... M9: ='Monthly Capacity'!M$37+'Growth & Hiring'!M$23 -> 122760.48 | N9: =SUM(B9:M9) -> 1245982.9 | P9: Σ billable revenue, all staff (Staff P&L)
A10: Total for Income | B10: =B8+B9 -> 96349.182 | C10: =C8+C9 -> 91069.76 | D10: =D8+D9 -> 101628.6 | E10: =E8+E9 -> 101628.6 | F10: =F8+F9 -> 91069.76 | G10: =G8+G9 -> 101628.6 | H10: =H8+H9 -> 101628.6 | I10: =I8+I9 -> 99349.182 | ... N10: =N8+N9 -> 1245982.9
A11: Cost of Goods Sold
A12: Cost of labor - Contractors | B12: ='Staff P&L'!$U$10 -> 4200 | C12: ='Staff P&L'!$U$10 -> 4200 | D12: ='Staff P&L'!$U$10 -> 4200 | E12: ='Staff P&L'!$U$10 -> 4200 | F12: ='Staff P&L'!$U$10 -> 4200 | G12: ='Staff P&L'!$U$10 -> 4200 | H12: ='Staff P&L'!$U$10 -> 4200 | I12: ='Staff P&L'!$U$10 -> 4200 | ... M12: ='Staff P&L'!$U$10 -> 4200 | N12: =SUM(B12:M12) -> 50400 | P12: Valentina (Bulgaria all-in)
A13: Filing Fees | B13: 28.48 | C13: 28.48 | D13: 28.48 | E13: 28.48 | F13: 28.48 | G13: 28.48 | H13: 28.48 | I13: 28.48 | J13: 28.48 | K13: 28.48 | L13: 28.48 | M13: 28.48 | N13: =SUM(B13:M13) -> 341.76 | P13: H1-26 avg ≈ $28/mo
A14: Payroll Expenses
A15: Discretionary Bonuses | B15: 0 | C15: 0 | D15: ='Staff P&L'!$D$25 -> 0 | E15: 0 | F15: 0 | G15: ='Staff P&L'!$E$25 -> 0 | H15: 0 | I15: 0 | J15: ='Staff P&L'!$F$25 -> 8852.8 | K15: 0 | L15: 0 | M15: ='Staff P&L'!$G$25 -> 8852.8 | N15: =SUM(B15:M15) -> 17705.6 | P15: Input
A16: Holiday Pay | B16: 0 | C16: 0 | D16: 0 | E16: 0 | F16: 0 | G16: 0 | H16: 0 | I16: 0 | J16: 0 | K16: 0 | L16: 0 | M16: 0 | N16: =SUM(B16:M16) -> 0 | P16: 0 — embedded in annual wages
A17: Wages | B17: ='Staff P&L'!$E$6/12*'Staff P&L'!$T$6+'Staff P&L'!$E$7/12*'Staff P&L'!$T$7+'Monthly Capacity'!B$40*'Staff P&L'!$T$8+'Monthly Capacity'!B$41*'Staff P&L'!$T$9+'Staff P&L'!$E$11/12*'Staff P&L'!$T$11+'Growth & Hiring'!B$24 -> 40954.167 | C17: ='Staff P&L'!$E$6/12*'Staff P&L'!$T$6+'Staff P&L'!$E$7/12*'Staff P&L'!$T$7+'Monthly Capacity'!C$40*'Staff P&L'!$T$8+'Monthly Capacity'!C$41*'Staff P&L'!$T$9+'Staff P&L'!$E$11/12*'Staff P&L'!$T$11+'Growth & Hiring'!C$24 -> 39354.167 | D17: ='Staff P&L'!$E$6/12*'Staff P&L'!$T$6+'Staff P&L'!$E$7/12*'Staff P&L'!$T$7+'Monthly Capacity'!D$40*'Staff P&L'!$T$8+'Monthly Capacity'!D$41*'Staff P&L'!$T$9+'Staff P&L'!$E$11/12*'Staff P&L'!$T$11+'Growth & Hiring'!D$24 -> 40954.167 | E17: ='Staff P&L'!$E$6/12*'Staff P&L'!$T$6+'Staff P&L'!$E$7/12*'Staff P&L'!$T$7+'Monthly Capacity'!E$40*'Staff P&L'!$T$8+'Monthly Capacity'!E$41*'Staff P&L'!$T$9+'Staff P&L'!$E$11/12*'Staff P&L'!$T$11+'Growth & Hiring'!E$24 -> 40954.167 | F17: ='Staff P&L'!$E$6/12*'Staff P&L'!$T$6+'Staff P&L'!$E$7/12*'Staff P&L'!$T$7+'Monthly Capacity'!F$40*'Staff P&L'!$T$8+'Monthly Capacity'!F$41*'Staff P&L'!$T$9+'Staff P&L'!$E$11/12*'Staff P&L'!$T$11+'Growth & Hiring'!F$24 -> 40154.167 | G17: ='Staff P&L'!$E$6/12*'Staff P&L'!$T$6+'Staff P&L'!$E$7/12*'Staff P&L'!$T$7+'Monthly Capacity'!G$40*'Staff P&L'!$T$8+'Monthly Capacity'!G$41*'Staff P&L'!$T$9+'Staff P&L'!$E$11/12*'Staff P&L'!$T$11+'Growth & Hiring'!G$24 -> 40954.167 | H17: ='Staff P&L'!$E$6/12*'Staff P&L'!$T$6+'Staff P&L'!$E$7/12*'Staff P&L'!$T$7+'Monthly Capacity'!H$40*'Staff P&L'!$T$8+'Monthly Capacity'!H$41*'Staff P&L'!$T$9+'Staff P&L'!$E$11/12*'Staff P&L'!$T$11+'Growth & Hiring'!H$24 -> 41754.167 | I17: ='Staff P&L'!$E$6/12*'Staff P&L'!$T$6+'Staff P&L'!$E$7/12*'Staff P&L'!$T$7+'Monthly Capacity'!I$40*'Staff P&L'!$T$8+'Monthly Capacity'!I$41*'Staff P&L'!$T$9+'Staff P&L'!$E$11/12*'Staff P&L'!$T$11+'Growth & Hiring'!I$24 -> 40154.167 | ... M17: ='Staff P&L'!$E$6/12*'Staff P&L'!$T$6+'Staff P&L'!$E$7/12*'Staff P&L'!$T$7+'Monthly Capacity'!M$40*'Staff P&L'!$T$8+'Monthly Capacity'!M$41*'Staff P&L'!$T$9+'Staff P&L'!$E$11/12*'Staff P&L'!$T$11+'Growth & Hiring'!M$24 -> 49379.375 | N17: =SUM(B17:M17) -> 511925.62 | P17: Production staff, COGS-allocated
